Workbook

Sheet 2026 Build Status
A1: Last Update | B1: 46230
A2: 2025 Sales Data - minimum 10 units annually | F2: Avail | G2: Open Mos | H2: Avg Monthly - OH and Open Mos
A3: SKU | B3: Description | C3: Grand Total | D3: Average Monthly | E3: Std Deviation | F3: Current On Hand | G3: In Process | H3: Needed | I3: Core Required | J3: Core Availability | K3: Total Cores Needed | L3: To Order
A4: RMT4500D-6 | B4: NV4500 M/T '98-'02 CHY 8.0L OR DSL, 5SPD, 4WD, CI CASE, ALUM TOP COVER | C4: 322 | D4: 27 | E4: 7 | F4: =IFERROR(GETPIVOTDATA("Sum of Avail",Inventory!$I$5,"Item",A4,"WH","MN1"),0) -> -5 | G4: =IFERROR(GETPIVOTDATA("Sum of Quantity",'MO Pivot'!$A$3,"DC","A-WH_MN1 ","SKU",A4),0) -> 7 | H4: =IF(D4-(F4+G4)<0,0,D4-(F4+G4)) -> 25 | I4: CORMT4500D-9 | J4: =IFERROR(GETPIVOTDATA("Sum of Avail",Inventory!$I$5,"Item",I4),"")&" in MN" -> 4 in MN | K4: =SUMIF(I:I,I4,H:H) -> 28 | L4: =IFERROR(IF(GETPIVOTDATA("Sum of Avail",Inventory!$I$5,"Item",I4)<K4,"ORDER CORES","Not"),"ORDER CORES") -> ORDER CORES
A5: RMTG56-2 | B5: G56 M/T '05-'18 CHY 5.9L & 6.7L, 6SPD, 4WD | C5: 265 | D5: 22 | E5: 5 | F5: =IFERROR(GETPIVOTDATA("Sum of Avail",Inventory!$I$5,"Item",A5,"WH","MN1"),0) -> -6 | G5: =IFERROR(GETPIVOTDATA("Sum of Quantity",'MO Pivot'!$A$3,"DC","A-WH_MN1 ","SKU",A5),0) -> 4 | H5: =IF(D5-(F5+G5)<0,0,D5-(F5+G5)) -> 24 | I5: CORMTG56-2 | J5: =IFERROR(GETPIVOTDATA("Sum of Avail",Inventory!$I$5,"Item",I5),"")&" in MN" -> 18 in MN | K5: =SUMIF(I:I,I5,H:H) -> 28 | L5: =IFERROR(IF(GETPIVOTDATA("Sum of Avail",Inventory!$I$5,"Item",I5)<K5,"ORDER CORES","Not"),"ORDER CORES") -> ORDER CORES
A6: RMT5600D-4 | B6: NV5600 M/T '99-'05 CHY 5.9L DSL, 6SPD, 4WD, 1.375" INP | C6: 250 | D6: 21 | E6: 7 | F6: =IFERROR(GETPIVOTDATA("Sum of Avail",Inventory!$I$5,"Item",A6,"WH","MN1"),0) -> 3 | G6: =IFERROR(GETPIVOTDATA("Sum of Quantity",'MO Pivot'!$A$3,"DC","A-WH_MN1 ","SKU",A6),0) -> 1 | H6: =IF(D6-(F6+G6)<0,0,D6-(F6+G6)) -> 17 | I6: CORMT5600D-4 | J6: =IFERROR(GETPIVOTDATA("Sum of Avail",Inventory!$I$5,"Item",I6),"")&" in MN" -> in MN | K6: =SUMIF(I:I,I6,H:H) -> 17 | L6: =IFERROR(IF(GETPIVOTDATA("Sum of Avail",Inventory!$I$5,"Item",I6)<K6,"ORDER CORES","Not"),"ORDER CORES") -> ORDER CORES
A7: RMTM5R2F-2 | B7: M/T '88-'96 FORD & MAZDA BRONCO, F150 & F250 5SPD, 4WD | C7: 200 | D7: 17 | E7: 5 | F7: =IFERROR(GETPIVOTDATA("Sum of Avail",Inventory!$I$5,"Item",A7,"WH","MN1"),0) -> 0 | G7: =IFERROR(GETPIVOTDATA("Sum of Quantity",'MO Pivot'!$A$3,"DC","A-WH_MN1 ","SKU",A7),0) -> 2 | H7: =IF(D7-(F7+G7)<0,0,D7-(F7+G7)) -> 15 | I7: CORMTM5R2F-2 | J7: =IFERROR(GETPIVOTDATA("Sum of Avail",Inventory!$I$5,"Item",I7),"")&" in MN" -> 7 in MN | K7: =SUMIF(I:I,I7,H:H) -> 15 | L7: =IFERROR(IF(GETPIVOTDATA("Sum of Avail",Inventory!$I$5,"Item",I7)<K7,"ORDER CORES","Not"),"ORDER CORES") -> ORDER CORES
A8: RMT3550J-3 | B8: NV3550 M/T '00-'04 JEEP TJ 5SPD, 4WD | C8: 160 | D8: 13 | E8: 3 | F8: =IFERROR(GETPIVOTDATA("Sum of Avail",Inventory!$I$5,"Item",A8,"WH","MN1"),0) -> 0 | G8: =IFERROR(GETPIVOTDATA("Sum of Quantity",'MO Pivot'!$A$3,"DC","A-WH_MN1 ","SKU",A8),0) -> 0 | H8: =IF(D8-(F8+G8)<0,0,D8-(F8+G8)) -> 13 | I8: CORMT3550J-3 | J8: =IFERROR(GETPIVOTDATA("Sum of Avail",Inventory!$I$5,"Item",I8),"")&" in MN" -> 29 in MN | K8: =SUMIF(I:I,I8,H:H) -> 13 | L8: =IFERROR(IF(GETPIVOTDATA("Sum of Avail",Inventory!$I$5,"Item",I8)<K8,"ORDER CORES","Not"),"ORDER CORES") -> Not
A9: RMTAX15J-8 | B9: AX15 M/T '97-'99 JEEP TJ 6CYL, 5SPD, 4WD, .75 PILOT TIP, W/EXT. SLAVE | C9: 150 | D9: 13 | E9: 5 | F9: =IFERROR(GETPIVOTDATA("Sum of Avail",Inventory!$I$5,"Item",A9,"WH","MN1"),0) -> 0 | G9: =IFERROR(GETPIVOTDATA("Sum of Quantity",'MO Pivot'!$A$3,"DC","A-WH_MN1 ","SKU",A9),0) -> 0 | H9: =IF(D9-(F9+G9)<0,0,D9-(F9+G9)) -> 13 | I9: CORMTAX15J-8 | J9: =IFERROR(GETPIVOTDATA("Sum of Avail",Inventory!$I$5,"Item",I9),"")&" in MN" -> 57 in MN | K9: =SUMIF(I:I,I9,H:H) -> 13 | L9: =IFERROR(IF(GETPIVOTDATA("Sum of Avail",Inventory!$I$5,"Item",I9)<K9,"ORDER CORES","Not"),"ORDER CORES") -> Not
A10: RMTS6-650F-6 | B10: ZF M/T '99-'00 FORD 7.3L, 6SPD, 4WD, 5.79-0.72 RATIO, 24SPL OUTPUT | C10: 142 | D10: 12 | E10: 5 | F10: =IFERROR(GETPIVOTDATA("Sum of Avail",Inventory!$I$5,"Item",A10,"WH","MN1"),0) -> -4 | G10: =IFERROR(GETPIVOTDATA("Sum of Quantity",'MO Pivot'!$A$3,"DC","A-WH_MN1 ","SKU",A10),0) -> 3 | H10: =IF(D10-(F10+G10)<0,0,D10-(F10+G10)) -> 13 | I10: CORMTS6-650F-6 | J10: =IFERROR(GETPIVOTDATA("Sum of Avail",Inventory!$I$5,"Item",I10),"")&" in MN" -> 14 in MN | K10: =SUMIF(I:I,I10,H:H) -> 13 | L10: =IFERROR(IF(GETPIVOTDATA("Sum of Avail",Inventory!$I$5,"Item",I10)<K10,"ORDER CORES","Not"),"ORDER CORES") -> Not
A11: RMT4500D-4 | B11: NV4500 M/T '94-'97 CHY 8.0L OR DSL, 5SPD, 4WD, CI CASE, ALUM TOP COVER | C11: 132 | D11: 11 | E11: 5 | F11: =IFERROR(GETPIVOTDATA("Sum of Avail",Inventory!$I$5,"Item",A11,"WH","MN1"),0) -> 0 | G11: =IFERROR(GETPIVOTDATA("Sum of Quantity",'MO Pivot'!$A$3,"DC","A-WH_MN1 ","SKU",A11),0) -> 1 | H11: =IF(D11-(F11+G11)<0,0,D11-(F11+G11)) -> 10 | I11: CORMT4500D-4 | J11: =IFERROR(GETPIVOTDATA("Sum of Avail",Inventory!$I$5,"Item",I11),"")&" in MN" -> 25 in MN | K11: =SUMIF(I:I,I11,H:H) -> 10 | L11: =IFERROR(IF(GETPIVOTDATA("Sum of Avail",Inventory!$I$5,"Item",I11)<K11,"ORDER CORES","Not"),"ORDER CORES") -> Not
A12: RMT4500D-5 | B12: ** SEE NOTE ** NV4500 M/T '98-'02 CHY 8.0L OR DSL, 5SPD, 2WD | C12: 120 | D12: 10 | E12: 4 | F12: =IFERROR(GETPIVOTDATA("Sum of Avail",Inventory!$I$5,"Item",A12,"WH","MN1"),0) -> 0 | G12: =IFERROR(GETPIVOTDATA("Sum of Quantity",'MO Pivot'!$A$3,"DC","A-WH_MN1 ","SKU",A12),0) -> 0 | H12: =IF(D12-(F12+G12)<0,0,D12-(F12+G12)) -> 10 | I12: CORMT4500D-12 | J12: =IFERROR(GETPIVOTDATA("Sum of Avail",Inventory!$I$5,"Item",I12),"")&" in MN" -> 1 in MN | K12: =SUMIF(I:I,I12,H:H) -> 10 | L12: =IFERROR(IF(GETPIVOTDATA("Sum of Avail",Inventory!$I$5,"Item",I12)<K12,"ORDER CORES","Not"),"ORDER CORES") -> ORDER CORES
A13: RMTNSG370-12 | B13: NSG370 M/T '12-'18 JEEP JK WRANGLER 3.6L, 6SPD, 4WD | C13: 106 | D13: 10 | E13: 4 | F13: =IFERROR(GETPIVOTDATA("Sum of Avail",Inventory!$I$5,"Item",A13,"WH","MN1"),0) -> 0 | G13: =IFERROR(GETPIVOTDATA("Sum of Quantity",'MO Pivot'!$A$3,"DC","A-WH_MN1 ","SKU",A13),0) -> 0 | H13: =IF(D13-(F13+G13)<0,0,D13-(F13+G13)) -> 10 | I13: CORMTNSG370-12 | J13: =IFERROR(GETPIVOTDATA("Sum of Avail",Inventory!$I$5,"Item",I13),"")&" in MN" -> 64 in MN | K13: =SUMIF(I:I,I13,H:H) -> 10 | L13: =IFERROR(IF(GETPIVOTDATA("Sum of Avail",Inventory!$I$5,"Item",I13)<K13,"ORDER CORES","Not"),"ORDER CORES") -> Not
A14: RMTM5R2F-3 | B14: M/T '92-'96 FORD & MAZDA F150 & F250 5SPD, 2WD, NO VSS OR SPEEDO | C14: 103 | D14: 9 | E14: 2 | F14: =IFERROR(GETPIVOTDATA("Sum of Avail",Inventory!$I$5,"Item",A14,"WH","MN1"),0) -> 0 | G14: =IFERROR(GETPIVOTDATA("Sum of Quantity",'MO Pivot'!$A$3,"DC","A-WH_MN1 ","SKU",A14),0) -> 0 | H14: =IF(D14-(F14+G14)<0,0,D14-(F14+G14)) -> 9 | I14: CORMTM5R2F-3 | J14: =IFERROR(GETPIVOTDATA("Sum of Avail",Inventory!$I$5,"Item",I14),"")&" in MN" -> 14 in MN | K14: =SUMIF(I:I,I14,H:H) -> 9 | L14: =IFERROR(IF(GETPIVOTDATA("Sum of Avail",Inventory!$I$5,"Item",I14)<K14,"ORDER CORES","Not"),"ORDER CORES") -> Not
A15: RMTAX5J-4 | B15: AX5 M/T '94-'95 JEEP YJ 5SPD, 4WD, EXT. SLAVE | C15: 85 | D15: 8 | E15: 6 | F15: =IFERROR(GETPIVOTDATA("Sum of Avail",Inventory!$I$5,"Item",A15,"WH","MN1"),0) -> 0 | G15: =IFERROR(GETPIVOTDATA("Sum of Quantity",'MO Pivot'!$A$3,"DC","A-WH_MN1 ","SKU",A15),0) -> 0 | H15: =IF(D15-(F15+G15)<0,0,D15-(F15+G15)) -> 8 | I15: CORMTAX5J-4 | J15: =IFERROR(GETPIVOTDATA("Sum of Avail",Inventory!$I$5,"Item",I15),"")&" in MN" -> 38 in MN | K15: =SUMIF(I:I,I15,H:H) -> 8 | L15: =IFERROR(IF(GETPIVOTDATA("Sum of Avail",Inventory!$I$5,"Item",I15)<K15,"ORDER CORES","Not"),"ORDER CORES") -> Not
... A105: RMTG360D-2 | B105: ** SEE NOTE ** G360 M/T '89-'93 CHY DSL, 5SPD, 2WD, CI CASE, ALUM TOP COVER | C105: 11 | D105: 1 | E105: 1 | F105: =IFERROR(GETPIVOTDATA("Sum of Avail",Inventory!$I$5,"Item",A105,"WH","MN1"),0) -> 0 | G105: =IFERROR(GETPIVOTDATA("Sum of Quantity",'MO Pivot'!$A$3,"DC","A-WH_MN1 ","SKU",A105),0) -> 0 | H105: =IF(D105-(F105+G105)<0,0,D105-(F105+G105)) -> 1 | I105: CORMTG360D-2 | J105: =IFERROR(GETPIVOTDATA("Sum of Avail",Inventory!$I$5,"Item",I105),"")&" in MN" -> 2 in MN | K105: =SUMIF(I:I,I105,H:H) -> 1 | L105: =IFERROR(IF(GETPIVOTDATA("Sum of Avail",Inventory!$I$5,"Item",I105)<K105,"ORDER CORES","Not"),"ORDER CORES") -> Not
A106: RMTDODTOPCOVER | B106: DODGE '89-93 DIESEL G360 5SPD TOP COVER-REBUILT ***SEE NOTE*** | C106: 11 | D106: 1 | E106: 1 | F106: =IFERROR(GETPIVOTDATA("Sum of Avail",Inventory!$I$5,"Item",A106,"WH","MN1"),0) -> 0 | G106: =IFERROR(GETPIVOTDATA("Sum of Quantity",'MO Pivot'!$A$3,"DC","A-WH_MN1 ","SKU",A106),0) -> 0 | H106: =IF(D106-(F106+G106)<0,0,D106-(F106+G106)) -> 1 | I106: #N/A | J106: =IFERROR(GETPIVOTDATA("Sum of Avail",Inventory!$I$5,"Item",I106),"")&" in MN" -> in MN | K106: =SUMIF(I:I,I106,H:H) -> 2 | L106: =IFERROR(IF(GETPIVOTDATA("Sum of Avail",Inventory!$I$5,"Item",I106)<K106,"ORDER CORES","Not"),"ORDER CORES") -> ORDER CORES
A107: RTC727 | B107: G760 T-CASE '10-'17 GM EQUINOX & TERRAIN 2.4L | C107: 11 | D107: 3 | E107: 1 | F107: =IFERROR(GETPIVOTDATA("Sum of Avail",Inventory!$I$5,"Item",A107,"WH","MN1"),0) -> 0 | G107: =IFERROR(GETPIVOTDATA("Sum of Quantity",'MO Pivot'!$A$3,"DC","A-WH_MN1 ","SKU",A107),0) -> 2 | H107: =IF(D107-(F107+G107)<0,0,D107-(F107+G107)) -> 1 | I107: #N/A | J107: =IFERROR(GETPIVOTDATA("Sum of Avail",Inventory!$I$5,"Item",I107),"")&" in MN" -> in MN | K107: =SUMIF(I:I,I107,H:H) -> 2 | L107: =IFERROR(IF(GETPIVOTDATA("Sum of Avail",Inventory!$I$5,"Item",I107)<K107,"ORDER CORES","Not"),"ORDER CORES") -> ORDER CORES
A108: RMT5C-10 | B108: T5 M/T '89-'93 GM S10, S15, JIMMY & SON 5SPD, 2WD, ALUM CASE, TAIL & TOP COVER, ELEC. SPEEDO | C108: 11 | D108: 1 | E108: 1 | F108: =IFERROR(GETPIVOTDATA("Sum of Avail",Inventory!$I$5,"Item",A108,"WH","MN1"),0) -> 0 | G108: =IFERROR(GETPIVOTDATA("Sum of Quantity",'MO Pivot'!$A$3,"DC","A-WH_MN1 ","SKU",A108),0) -> 0 | H108: =IF(D108-(F108+G108)<0,0,D108-(F108+G108)) -> 1 | I108: CORMT5C-10 | J108: =IFERROR(GETPIVOTDATA("Sum of Avail",Inventory!$I$5,"Item",I108),"")&" in MN" -> 20 in MN | K108: =SUMIF(I:I,I108,H:H) -> 1 | L108: =IFERROR(IF(GETPIVOTDATA("Sum of Avail",Inventory!$I$5,"Item",I108)<K108,"ORDER CORES","Not"),"ORDER CORES") -> Not
A109: RMT4500C-12 | B109: NV4500 M/T '94-'95 GM C3500HD 2WD, EXT. SLAVE, SQUARE TOP COVER, W/ E-BRAKE | C109: 10 | D109: 1 | E109: 0 | F109: =IFERROR(GETPIVOTDATA("Sum of Avail",Inventory!$I$5,"Item",A109,"WH","MN1"),0) -> 0 | G109: =IFERROR(GETPIVOTDATA("Sum of Quantity",'MO Pivot'!$A$3,"DC","A-WH_MN1 ","SKU",A109),0) -> 0 | H109: =IF(D109-(F109+G109)<0,0,D109-(F109+G109)) -> 1 | I109: CORMT4500C-12 | J109: =IFERROR(GETPIVOTDATA("Sum of Avail",Inventory!$I$5,"Item",I109),"")&" in MN" -> 3 in MN | K109: =SUMIF(I:I,I109,H:H) -> 1 | L109: =IFERROR(IF(GETPIVOTDATA("Sum of Avail",Inventory!$I$5,"Item",I109)<K109,"ORDER CORES","Not"),"ORDER CORES") -> Not
A110: RMTM5R2F-7 | B110: M/T '97-'98 FORD & MAZDA F150 & F250 V8, 5SPD, 4WD | C110: 10 | D110: 1 | E110: 1 | F110: =IFERROR(GETPIVOTDATA("Sum of Avail",Inventory!$I$5,"Item",A110,"WH","MN1"),0) -> 0 | G110: =IFERROR(GETPIVOTDATA("Sum of Quantity",'MO Pivot'!$A$3,"DC","A-WH_MN1 ","SKU",A110),0) -> 0 | H110: =IF(D110-(F110+G110)<0,0,D110-(F110+G110)) -> 1 | I110: CORMTM5R2F-7 | J110: =IFERROR(GETPIVOTDATA("Sum of Avail",Inventory!$I$5,"Item",I110),"")&" in MN" -> 18 in MN | K110: =SUMIF(I:I,I110,H:H) -> 1 | L110: =IFERROR(IF(GETPIVOTDATA("Sum of Avail",Inventory!$I$5,"Item",I110)<K110,"ORDER CORES","Not"),"ORDER CORES") -> Not
A111: RMT51936 | B111: ** NLA ** 0A4 M/T '12-'16 VW BEETLE '12-'15 VW PASSAT, 1.8L & 2.5L 5SPD | C111: 10 | D111: 1 | E111: 1 | F111: =IFERROR(GETPIVOTDATA("Sum of Avail",Inventory!$I$5,"Item",A111,"WH","MN1"),0) -> 0 | G111: =IFERROR(GETPIVOTDATA("Sum of Quantity",'MO Pivot'!$A$3,"DC","A-WH_MN1 ","SKU",A111),0) -> 0 | H111: =IF(D111-(F111+G111)<0,0,D111-(F111+G111)) -> 1 | I111: CORMT51936 | J111: =IFERROR(GETPIVOTDATA("Sum of Avail",Inventory!$I$5,"Item",I111),"")&" in MN" -> in MN | K111: =SUMIF(I:I,I111,H:H) -> 1 | L111: =IFERROR(IF(GETPIVOTDATA("Sum of Avail",Inventory!$I$5,"Item",I111)<K111,"ORDER CORES","Not"),"ORDER CORES") -> ORDER CORES
A112: RMTS6-750F-1 | B112: ZF M/T '03-'07 FORD 6.0L, 6SPD, 2WD, 5.79-0.72 RATIO, ELEC. SPEEDO | C112: 10 | D112: 1 | E112: 1 | F112: =IFERROR(GETPIVOTDATA("Sum of Avail",Inventory!$I$5,"Item",A112,"WH","MN1"),0) -> 0 | G112: =IFERROR(GETPIVOTDATA("Sum of Quantity",'MO Pivot'!$A$3,"DC","A-WH_MN1 ","SKU",A112),0) -> 0 | H112: =IF(D112-(F112+G112)<0,0,D112-(F112+G112)) -> 1 | I112: CORMTS6-750F-1 | J112: =IFERROR(GETPIVOTDATA("Sum of Avail",Inventory!$I$5,"Item",I112),"")&" in MN" -> 9 in MN | K112: =SUMIF(I:I,I112,H:H) -> 1 | L112: =IFERROR(IF(GETPIVOTDATA("Sum of Avail",Inventory!$I$5,"Item",I112)<K112,"ORDER CORES","Not"),"ORDER CORES") -> Not
A113: RMTS5-42-12-P | B113: ** SEE NOTE ** ZF M/T '87-'95 FORD 6.9L & 7.3L, 5SPD, 4WD, 5.72-0.76 | C113: 10 | D113: 1 | E113: 1 | F113: =IFERROR(GETPIVOTDATA("Sum of Avail",Inventory!$I$5,"Item",A113,"WH","MN1"),0) -> 1 | G113: =IFERROR(GETPIVOTDATA("Sum of Quantity",'MO Pivot'!$A$3,"DC","A-WH_MN1 ","SKU",A113),0) -> 0 | H113: =IF(D113-(F113+G113)<0,0,D113-(F113+G113)) -> 0 | I113: CORMTS5-42-14 | J113: =IFERROR(GETPIVOTDATA("Sum of Avail",Inventory!$I$5,"Item",I113),"")&" in MN" -> 2 in MN | K113: =SUMIF(I:I,I113,H:H) -> 4 | L113: =IFERROR(IF(GETPIVOTDATA("Sum of Avail",Inventory!$I$5,"Item",I113)<K113,"ORDER CORES","Not"),"ORDER CORES") -> ORDER CORES

Sheet MO Pivot
C3: Values
A4: DC | B4: SKU | C4: Count of MO# | D4: Sum of Quantity
A5: A-WH_IA1 | B5: RTC1626G-1 | C5: 1 | D5: 1
B6: RTC241J-7 | C6: 2 | D6: 2
B7: RTC246G-2 | C7: 3 | D7: 3
B8: RTC246G-2M | C8: 1 | D8: 1
B9: RTC261GHD-1 | C9: 1 | D9: 1
B10: RTC263GHD-2 | C10: 1 | D10: 1
B11: RTC263GXHD-2 | C11: 2 | D11: 2
B12: RTC271D-1 | C12: 2 | D12: 2
B13: RTC271F-1 | C13: 2 | D13: 2
B14: RTC271F-4 | C14: 2 | D14: 2
B15: RTC273D-1 | C15: 4 | D15: 4
B16: RTC273D-3 | C16: 2 | D16: 2
B17: RTC273D-4 | C17: 4 | D17: 4
... B53: RTC241DHD-4 | C53: 1 | D53: 1
A54: A-WH_IA1 Total | C54: 90 | D54: 90
A55: A-WH_MN1 | B55: NTC261GXHD-Q | C55: 18 | D55: 18
B56: RAA440-1337A | C56: 2 | D56: 2
B57: RAAMIS | C57: 5 | D57: 5
B58: RMT1393 | C58: 1 | D58: 1
B59: RMT4500D-4 | C59: 1 | D59: 1
B60: RMT4500D-6 | C60: 7 | D60: 7
B61: RMT5600D-4 | C61: 1 | D61: 1
B62: RMTG56-2 | C62: 4 | D62: 4
B63: RMTM5R2F-2 | C63: 2 | D63: 2
B64: RMTS5-47-6 | C64: 1 | D64: 1
B65: RMTS6-650F-6 | C65: 3 | D65: 3
B66: RTC1128F-1 | C66: 1 | D66: 1
B67: RTC1628F-1M | C67: 1 | D67: 1
... B156: MK D50-STRAIGHT | C156: 1 | D156: 1
A157: A-WH_MN1 Total | C157: 183 | D157: 456
A158: Grand Total | C158: 273 | D158: 546

Sheet Open MOs
A1: DC | B1: MO# | C1: MO Status | D1: Parent | E1: Quantity | F1: SKU
A2: A-WH_TX1 | B2: 724508 | C2: Released | D2: PVTOR630446 | E2: 10 | F2: =TRIM(Material_Orders[[#This Row],[Parent]]) -> PVTOR630446
A3: A-WH_TX1 | B3: 700553 | C3: Released | D3: YK GM8.6-A | E3: 3 | F3: =TRIM(Material_Orders[[#This Row],[Parent]]) -> YK GM8.6-A
A4: A-WH_TX1 | B4: 730242 | C4: Released | D4: YA FBRONCO-3-31 | E4: 1 | F4: =TRIM(Material_Orders[[#This Row],[Parent]]) -> YA FBRONCO-3-31
A5: A-WH_CA1 | B5: 728494 | C5: Released | D5: YC D74209 | E5: 18 | F5: =TRIM(Material_Orders[[#This Row],[Parent]]) -> YC D74209
A6: A-WH_MN1 | B6: 730194 | C6: Released | D6: RAAMIS | E6: 1 | F6: =TRIM(Material_Orders[[#This Row],[Parent]]) -> RAAMIS
A7: A-WH_TX1 | B7: 730682 | C7: Released | D7: PVTOR630213 | E7: 2 | F7: =TRIM(Material_Orders[[#This Row],[Parent]]) -> PVTOR630213
A8: A-WH_CA1 | B8: 709870 | C8: Released | D8: ZK GM8.25IFS-B | E8: 1 | F8: =TRIM(Material_Orders[[#This Row],[Parent]]) -> ZK GM8.25IFS-B
A9: A-WH_CA1 | B9: 726776 | C9: Released | D9: YK AAM11.5-C | E9: 16 | F9: =TRIM(Material_Orders[[#This Row],[Parent]]) -> YK AAM11.5-C
A10: A-WH_CA1 | B10: 710452 | C10: Released | D10: ZG C8.25-390 | E10: 1 | F10: =TRIM(Material_Orders[[#This Row],[Parent]]) -> ZG C8.25-390
A11: A-WH_TX1 | B11: 693527 | C11: Released | D11: USA630330 | E11: 1 | F11: =TRIM(Material_Orders[[#This Row],[Parent]]) -> USA630330
A12: A-WH_MN1 | B12: 730182 | C12: Released | D12: RMTS5-42-14 | E12: 1 | F12: =TRIM(Material_Orders[[#This Row],[Parent]]) -> RMTS5-42-14
A13: A-WH_CA1 | B13: 722112 | C13: Released | D13: MDWD-3 | E13: 1 | F13: =TRIM(Material_Orders[[#This Row],[Parent]]) -> MDWD-3
... A2327: A-WH_MN1 | B2327: 731297 | C2327: Released | D2327: RTC271D-4 | E2327: 1 | F2327: =TRIM(Material_Orders[[#This Row],[Parent]]) -> RTC271D-4

Sheet Inventory
A1: Item | B1: WH | C1: OH | D1: Avail
A2: 1008 | B2: CA1 | C2: 1 | D2: 1
A3: 1008 | B3: KY1 | C3: 1 | D3: 1
A4: 1008 | B4: TX1 | C4: 3 | D4: 3 | L4: =Inventory!K16973 -> 28
A5: 1008 | B5: WA1 | C5: 2 | D5: 2 | K5: Values
A6: 1025 | B6: TX1 | C6: 4 | D6: 4 | I6: Item | J6: WH | K6: Sum of OH | L6: Sum of Avail
A7: 1037 | B7: TX1 | C7: 76 | D7: 63 | I7: 1008 | J7: CA1 | K7: 1 | L7: 1
A8: 1043 | B8: TX1 | C8: 71 | D8: 58 | J8: KY1 | K8: 1 | L8: 1
A9: 1043 | B9: WA1 | C9: 1 | D9: 1 | J9: TX1 | K9: 3 | L9: 3
A10: 1046 | B10: TX1 | C10: 1 | D10: 1 | J10: WA1 | K10: 2 | L10: 2
A11: 1051 | B11: TX1 | C11: 14 | D11: 14 | I11: 1008 Total | K11: 7 | L11: 7
A12: 1052 | B12: TX1 | C12: 2 | D12: 2 | I12: 1025 | J12: TX1 | K12: 4 | L12: 4
A13: 1057 | B13: TX1 | C13: 1 | D13: 1 | I13: 1025 Total | K13: 4 | L13: 4
A14: 1057 | B14: WA1 | C14: 1 | D14: 1 | I14: 1037 | J14: TX1 | K14: 76 | L14: 63
A15: 1058 | B15: TX1 | C15: 3 | D15: 3 | I15: 1037 Total | K15: 76 | L15: 63
A16: 1059 | B16: TX1 | C16: 1 | D16: 1 | I16: 1046 | J16: TX1 | K16: 1 | L16: 1
A17: 1061 | B17: TX1 | C17: 1 | D17: 1 | I17: 1046 Total | K17: 1 | L17: 1
A18: 1062 | B18: TX1 | C18: 1 | D18: 1 | I18: 1058 | J18: TX1 | K18: 3 | L18: 3
A19: 1062 | B19: WA1 | C19: 1 | D19: 1 | I19: 1058 Total | K19: 3 | L19: 3
A20: 110-90190 | B20: KY1 | C20: 11 | D20: 10 | I20: 1059 | J20: TX1 | K20: 1 | L20: 1
A21: 110-90244 | B21: KY1 | C21: 18 | D21: 16 | I21: 1059 Total | K21: 1 | L21: 1
A22: 110-90246 | B22: KY1 | C22: 10 | D22: 10 | I22: 1061 | J22: TX1 | K22: 1 | L22: 1
A23: 110-90252 | B23: KY1 | C23: 12 | D23: 9 | I23: 1061 Total | K23: 1 | L23: 1
A24: 110-90253 | B24: KY1 | C24: 20 | D24: 19 | I24: 110-90190 | J24: KY1 | K24: 11 | L24: 10
A25: 110-90253 | B25: WA1 | C25: 2 | D25: 2 | I25: 110-90190 Total | K25: 11 | L25: 10
A26: 110-90255 | B26: KY1 | C26: 18 | D26: 18 | I26: 110-90246 | J26: KY1 | K26: 10 | L26: 10
A27: 110-90258 | B27: KY1 | C27: 24 | D27: 22 | I27: 110-90246 Total | K27: 10 | L27: 10
A28: 110-90259 | B28: KY1 | C28: 11 | D28: 6 | I28: 110-90252 | J28: KY1 | K28: 12 | L28: 9
A29: 110-90269 | B29: KY1 | C29: 12 | D29: 12 | I29: 110-90252 Total | K29: 12 | L29: 9
A30: 110-90270 | B30: KY1 | C30: 7 | D30: 7 | I30: 110-90253 | J30: KY1 | K30: 20 | L30: 19
A31: 110-90272 | B31: KY1 | C31: 4 | D31: 4 | J31: WA1 | K31: 2 | L31: 2
A32: 110-90277 | B32: KY1 | C32: 13 | D32: 12 | I32: 110-90253 Total | K32: 22 | L32: 21
A33: 110-90277 | B33: MN1 | C33: 1 | D33: 1 | I33: 110-90258 | J33: KY1 | K33: 24 | L33: 22
A34: 110-90278 | B34: KY1 | C34: 6 | D34: 6 | I34: 110-90258 Total | K34: 24 | L34: 22
A35: 110-90283 | B35: KY1 | C35: 9 | D35: 7 | I35: 110-90259 | J35: KY1 | K35: 11 | L35: 6
A36: 110-90284 | B36: KY1 | C36: 12 | D36: 11 | I36: 110-90259 Total | K36: 11 | L36: 6
A37: 110-90285 | B37: KY1 | C37: 5 | D37: 5 | I37: 110-90269 | J37: KY1 | K37: 12 | L37: 12
A38: 110-90289 | B38: KY1 | C38: 4 | D38: 3 | I38: 110-90269 Total | K38: 12 | L38: 12
A39: 110-90295 | B39: KY1 | C39: 70 | D39: 65 | I39: 110-90270 | J39: KY1 | K39: 7 | L39: 7
A40: 110-90591 | B40: KY1 | C40: 9 | D40: 7 | I40: 110-90270 Total | K40: 7 | L40: 7
...

Sheet Core Look Up
A1: ZD SKU | B1: Core SKU
A2: RMT10052 | B2: CORMT10052
A3: RMT10103 | B3: CORMT10103
A4: RMT10201 | B4: CORMT10201
A5: RMT10500 | B5: CORMT10500
A6: RMT10984 | B6: CORMT10984
A7: RMT1120 | B7: CORMT1120
A8: RMT1126 | B8: CORMT1126
A9: RMT1256 | B9: CORMT1256
A10: RMT1383 | B10: CORMT1393
A11: RMT1383 | B11: CORMT1383
A12: RMT1393 | B12: CORMT1393
... A462: RMTZFB-E | B462: CORMTZFB-E
